Workbook

Sheet Catalogue_KPI
A1: KPI | B1: Définition | C1: Mode de calcul | D1: Unité | E1: Périmètre (Filière) | F1: Fréquence | G1: Source | H1: Responsable | I1: Baseline | J1: Objectif (valeur) | K1: Sens (↑/↓/=) | L1: Horizon | M1: Objectif-type (texte)
A2: Nb besoins par filière | B2: Volume de besoins par filière d’excellence. | C2: Comptage besoins tagués filière. | D2: nb | E2: FEA-ARCHITECTURE | F2: Mensuel | G2: Boond / CRM | H2: LF+DT | J2: +20% vs N-1 | K2: ↑ | L2: 31/12/2026 | M2: Augmenter le nombre de besoins par filière de +20% vs N-1 d’ici le 31/12/2026 (suivi mensuel).
A3: Nb candidats en vivier par filière | B3: Taille du vivier par filière. | C3: Comptage profils actifs dans le vivier. | D3: nb | E3: FEA-ARCHITECTURE | F3: Mensuel | G3: Boond / CRM | H3: LF+DT | J3: +30% vs N-1 | K3: ↑ | L3: 31/12/2026 | M3: Croître le vivier par filière de +30% vs N-1 d’ici le 31/12/2026; minimum +5%/mois sur 2026.
A4: Croissance vivier par filière | B4: Évolution du vivier par filière. | C4: Δ vivier filière / période. | D4: %/mois | E4: FEA-ARCHITECTURE | F4: Mensuel | G4: Boond / CRM | H4: LF+DT | J4: ≥ 5 %/mois | K4: ↑ | L4: 31/12/2026 | M4: Assurer une croissance du vivier ≥ 5% par mois sur 2026; ≥ 30% cumulé à fin 2026.
A5: Taux de réponse brute par filière | B5: Réactivité de réponse par filière. | C5: Réponses envoyées / besoins exprimés (filière). | D5: % | E5: FEA-ARCHITECTURE | F5: Mensuel | G5: Boond / CRM | H5: LF+DT | J5: ≥ 90 % | K5: ↑ | L5: 31/12/2026 | M5: Atteindre un taux de réponse brute ≥ 90% par filière chaque mois d’ici le 31/12/2026.
A6: Taux de réponse net par filière | B6: Pertinence perçue par filière. | C6: Réponses avec retour / besoins exprimés (filière). | D6: % | E6: FEA-ARCHITECTURE | F6: Mensuel | G6: Boond / CRM | H6: LF+DT | J6: ≥ 70 % | K6: ↑ | L6: 31/12/2026 | M6: Atteindre un taux de réponse net ≥ 70% par filière chaque mois d’ici le 31/12/2026.
A7: Taux de soutenance par besoin par filière | B7: Mobilisation soutenances par filière. | C7: Soutenances / besoins (filière). | D7: % | E7: FEA-ARCHITECTURE | F7: Mensuel | G7: Boond / CRM | H7: LF+DT | J7: ≥ 60 % | K7: ↑ | L7: 31/12/2026 | M7: Atteindre un taux de soutenance ≥ 60% par besoin et par filière chaque trimestre jusqu’au 31/12/2026.
A8: Taux de transformation par filière | B8: Conversion par filière. | C8: Missions gagnées / propositions (filière). | D8: % | E8: FEA-ARCHITECTURE | F8: Mensuel | G8: Boond / CRM | H8: LF+DT | J8: ≥ 25 % | K8: ↑ | L8: 31/12/2026 | M8: Atteindre un taux de transformation ≥ 25% par filière d’ici le 31/12/2026.
A9: Taux de conversion après soutenance par filière | B9: Efficacité soutenance par filière. | C9: Missions gagnées / soutenances (filière). | E9: FEA-ARCHITECTURE | F9: Mensuel | G9: Boond / CRM | H9: LF+DT | M9: ≥ 30 %
A10: Taux de rebond consultant par filière | B10: Fidélisation par filière. | C10: Consultants en rebond / fins de mission (filière). | E10: FEA-ARCHITECTURE | F10: Mensuel | G10: Boond / CRM | H10: LF+DT | M10: ≥ 50 %
A11: Taux de churn consultant par filière | B11: Attrition par filière. | C11: Consultants sortis / actifs (filière). | E11: FEA-ARCHITECTURE | F11: Mensuel | G11: Boond / CRM | H11: LF+DT | M11: < 10 %
A12: Nb d’offres packagées par filière | B12: Industrialisation de l’offre par filière. | C12: Comptage offres packagées actives. | D12: nb/an | E12: FEA-ARCHITECTURE | F12: Mensuel | G12: Boond / CRM | H12: LF+DT | J12: ≥ 2 | K12: ↑ | L12: 31/12/2026 | M12: Disposer d’au moins 2 offres packagées actives par filière au 31/12/2026.
A13: Taux de succès offres packagées par filière | B13: Performance des offres packagées. | C13: Gagnées / présentées (filière). | D13: % | E13: FEA-ARCHITECTURE | F13: Mensuel | G13: Boond / CRM | H13: LF+DT | J13: ≥ 35 % | K13: ↑ | L13: 31/12/2026 | M13: Atteindre un taux de succès des offres packagées ≥ 35% par filière d’ici le 31/12/2026.
A14: Nb de référencements par filière | B14: Ancrage client par filière. | C14: Comptage référencements par filière. | D14: nb/an | E14: FEA-ARCHITECTURE | F14: Mensuel | G14: Boond / CRM | H14: LF+DT | J14: ≥ 2 | K14: ↑ | L14: 31/12/2026 | M14: Obtenir ≥ 2 nouveaux référencements par filière en 2026 (échéance 31/12/2026).
A15: Taux de succès AO complexes par filière | B15: Performance sur AO complexes par filière. | C15: AO gagnés / répondus (filière). | D15: % | E15: FEA-ARCHITECTURE | F15: Mensuel | G15: Boond / CRM | H15: LF+DT | J15: ≥ 30 % | K15: ↑ | L15: 31/12/2026 | M15: Atteindre un taux de succès ≥ 30% sur AO complexes par filière d’ici le 31/12/2026.
A16: Nb de régies éligibles à une bascule CDS par filière | B16: Opportunités CDS détectées (filière). | C16: Comptage régies 'éligibles CDS' (filière). | D16: nb | E16: FEA-ARCHITECTURE | F16: Mensuel | G16: Boond / CRM | H16: LF+DT | J16: +50% vs N-1 | K16: ↑ | L16: 31/12/2026 | M16: Augmenter de +50% vs N-1 le nombre de régies éligibles CDS par filière d’ici le 31/12/2026.
A17: Nb de tentatives de bascule CDS par filière | B17: Effort de transformation par filière. | C17: Comptage tentatives (filière). | D17: nb/trim | E17: FEA-ARCHITECTURE | F17: Mensuel | G17: Boond / CRM | H17: LF+DT | J17: ≥ 1 | K17: ↑ | L17: 31/12/2026 | M17: Réaliser au moins 1 tentative de bascule CDS par filière et par trimestre jusqu’au 31/12/2026.
A18: Nb de bascules CDS réussies par filière | B18: Succès de transformation (filière). | C18: Comptage bascules réussies (filière). | D18: nb/trim | E18: FEA-ARCHITECTURE | F18: Mensuel | G18: Boond / CRM | H18: LF+DT | J18: ≥ 1 | K18: ↑ | L18: 31/12/2026 | M18: Obtenir au moins 1 bascule CDS réussie par filière et par trimestre jusqu’au 31/12/2026.
A19: Taux de bascule régie → CDS par filière | B19: Efficacité de transformation (filière). | C19: Bascules réussies / régies éligibles (filière). | E19: FEA-ARCHITECTURE | F19: Mensuel | G19: Boond / CRM | H19: LF+DT | M19: 10–20 %
A20: CA gagné via bascule CDS par filière | B20: Impact financier des bascules par filière. | C20: Σ (CA CDS – CA régie) (filière). | D20: € (Δ CA) | E20: FEA-ARCHITECTURE | F20: Mensuel | G20: Boond / CRM | H20: LF+DT | J20: +20% vs N-1 | K20: ↑ | L20: 31/12/2026 | M20: Accroître le CA net généré par les bascules CDS d’au moins +20% vs N-1 d’ici le 31/12/2026.
A21: Répartition motifs d’échec bascule par filière | B21: Analyse des causes d’échec par filière. | C21: % par motif. | D21: % | E21: FEA-ARCHITECTURE | F21: Mensuel | G21: Boond / CRM | H21: LF+DT | J21: Top 2 < 25 % chacun | K21: ↓ | L21: 31/12/2026 | M21: Ramener chacun des 2 motifs dominants d’échec < 25% d’ici le 31/12/2026.
A22: Délai moyen de réponse à AO par filière | B22: Réactivité AO par filière. | C22: Date réponse - date réception (moyenne) (filière). | E22: FEA-ARCHITECTURE | F22: Mensuel | G22: Boond / CRM | H22: LF+DT | M22: DT <24h ; AT <48h ; LF <24h
A23: Taux de transformation par délai (<48h, <7j, >7j) par filière | B23: Lien délai ↔ succès par filière. | C23: Taux de succès par tranche (filière). | E23: FEA-ARCHITECTURE | F23: Mensuel | G23: Boond / CRM | H23: LF+DT | M23: Maximiser <48h
A24: % candidats pertinents avec dossier prêt à l’emploi (par filière) | B24: Disponibilité des dossiers par filière. | C24: Nb candidats pertinents avec dossier / nb pertinents (filière). | E24: FEA-ARCHITECTURE | F24: Mensuel | G24: Boond / CRM | H24: LF+DT | M24: 100 %
A25: % dossiers validés par un LF (par filière) | B25: Qualité technique garantie par filière. | C25: Nb dossiers validés / nb créés (filière). | E25: FEA-ARCHITECTURE | F25: Mensuel | G25: Boond / CRM | H25: LF+DT | M25: 100 %
A26: % candidats avec références collectées (par filière) | B26: Réflexe de collecte par filière. | C26: Nb candidats avec refs / nb entretiens (filière). | E26: FEA-ARCHITECTURE | F26: Mensuel | G26: Boond / CRM | H26: LF+DT | M26: 100 %
A27: % candidats avec ≥1 référence vérifiée (par filière) | B27: Crédibilisation par filière. | C27: Nb candidats avec ≥1 ref vérifiée / nb candidats proposés (filière). | E27: FEA-ARCHITECTURE | F27: Mensuel | G27: Boond / CRM | H27: LF+DT | M27: 100 %
A28: % consultants préparés avant entretien (par filière) | B28: Qualité de préparation par filière. | C28: Nb consultants préparés / nb envoyés en entretien (filière). | E28: FEA-ARCHITECTURE | F28: Mensuel | G28: Boond / CRM | H28: LF+DT | M28: 100 %
A29: Nb de typologies de missions récurrentes identifiées par filière | B29: Cartographie des postes récurrents par filière. | C29: Comptage typologies récurrentes actives. | D29: nb | E29: FEA-ARCHITECTURE | F29: Mensuel | G29: Boond / CRM | H29: LF+DT | J29: ≥ 3 | K29: ↑ | L29: 30/06/2026 | M29: Identifier ≥ 3 typologies de missions récurrentes par filière d’ici le 30/06/2026.
A30: % besoins récurrents couverts par une fiche référence | B30: Industrialisation (fiche poste, TJM, soft skills). | C30: Nb typologies avec fiche / nb typologies cibles. | E30: FEA-ARCHITECTURE | F30: Mensuel | G30: Boond / CRM | H30: LF+DT | M30: 100 %
A31: Nb de viviers actifs par typologie récurrente | B31: Nombre de viviers maintenus par typologie. | C31: Comptage viviers actifs. | D31: nb/typologie | E31: FEA-ARCHITECTURE | F31: Mensuel | G31: Boond / CRM | H31: LF+DT | J31: ≥ 1 | K31: ↑ | L31: 31/03/2026 | M31: Disposer d’au moins 1 vivier actif par typologie récurrente d’ici le 31/03/2026.
A32: Nb moyen de profils disponibles par vivier | B32: Capacité à répondre immédiatement. | C32: Moyenne nb profils disponibles par vivier. | D32: nb/vivier | E32: FEA-ARCHITECTURE | F32: Mensuel | G32: Boond / CRM | H32: LF+DT | J32: ≥ 3 | K32: ↑ | L32: 30/06/2026 | M32: Assurer ≥ 3 profils disponibles par vivier d’ici le 30/06/2026.
A33: Taux de complétude des viviers (≥3 profils par typologie) | B33: Couverture des typologies récurrentes. | C33: Typologies avec ≥3 profils / nb typologies. | E33: FEA-ARCHITECTURE | F33: Mensuel | G33: Boond / CRM | H33: LF+DT | M33: 100 % sur sites majeurs
A34: Délai de mise à disposition d’un vivier | B34: Temps pour alimenter un vivier après identification. (Mesure la réactivité de votre organisation pour anticiper les besoins.) | C34: Date constitution vivier - date identification. | D34: jours ouvrés | E34: FEA-ARCHITECTURE | F34: Mensuel | G34: Boond / CRM | H34: LF+DT | J34: ≤ 10 jours | K34: ↓ | L34: 30/09/2026 | M34: Réduire le délai de mise à disposition d’un vivier à ≤ 10 jours ouvrés d’ici le 30/09/2026.
A35: Taux de couverture site-client (≥3 profils par site majeur) | B35: Capacité à livrer par site-clé. | C35: % typologies avec ≥3 profils par site. | E35: FEA-ARCHITECTURE | F35: Mensuel | G35: Boond / CRM | H35: LF+DT | M35: 100 % sites majeurs
A36: Taux de présentation express (<1h, 3 profils présentés) | B36: Réactivité 'time-to-present'. | C36: Nb cas avec 3 profils <1h / nb besoins récurrents. | E36: FEA-ARCHITECTURE | F36: Mensuel | G36: Boond / CRM | H36: LF+DT | M36: 100 %
A37: Nb de besoins de sourcing transmis aux DT par typologie/filière | B37: Synchronisation LF→DT. | C37: Comptage besoins transmis aux DT. | D37: % | E37: FEA-ARCHITECTURE | F37: Mensuel | G37: Boond / CRM | H37: LF+DT | K37: ↑ | L37: 30/06/2026 | M37: Transmettre 100% des besoins de sourcing récurrents aux DT d’ici le 30/06/2026.
A38: % de viviers construits avec apport DT vs LF direct | B38: Répartition de la construction vivier. | C38: Viviers apportés DT / viviers totaux. | D38: % (DT) | E38: FEA-ARCHITECTURE | F38: Mensuel | G38: Boond / CRM | H38: LF+DT | J38: 60 % (±10 pts) | K38: = | L38: 31/12/2026 | M38: Atteindre un équilibre de construction des viviers à 60% apport DT (±10 pts) d’ici le 31/12/2026.
A39: Taux de renouvellement des viviers (profils mis à jour / 6 mois) | B39: Fraîcheur des viviers. | C39: Profils mis à jour / profils vivier (6 mois). | E39: FEA-ARCHITECTURE | F39: Mensuel | G39: Boond / CRM | H39: LF+DT | M39: ≥ 80 %
A40: % de prestations en régie (par filière) | B40: Part des missions en régie dans la filière considérée. | C40: Nb missions régie (filière) / Nb missions totales (filière). | E40: FEA-ARCHITECTURE | F40: Mensuel | G40: Boond / CRM | H40: LF+DT | M40: < 70 % à horizon 2026
...

Sheet Audit_SMART
A1: KPI | B1: Priorité | C1: Mesure | D1: Indication | E1: Objectif-type | F1: Specific(S) | G1: Measurable(M) | H1: Achievable(A) | I1: Relevant(R) | J1: Time-bound(T) | K1: SMART? | L1: Problèmes
A2: Nb besoins par filière | B2: 1 | C2: Volume de besoins par filière d’excellence. | D2: Comptage besoins tagués filière. | E2: Augmenter le nombre de besoins par filière de +20% vs N-1 d’ici le 31/12/2026 (suivi mensuel). | F2: TRUE | G2: TRUE | H2: TRUE | I2: TRUE | J2: TRUE | K2: TRUE
A3: Nb candidats en vivier par filière | B3: 1 | C3: Taille du vivier par filière. | D3: Comptage profils actifs dans le vivier. | E3: Croître le vivier par filière de +30% vs N-1 d’ici le 31/12/2026; minimum +5%/mois sur 2026. | F3: TRUE | G3: TRUE | H3: TRUE | I3: TRUE | J3: TRUE | K3: TRUE
A4: Croissance vivier par filière | B4: 1 | C4: Évolution du vivier par filière. | D4: Δ vivier filière / période. | E4: Assurer une croissance du vivier ≥ 5% par mois sur 2026; ≥ 30% cumulé à fin 2026. | F4: TRUE | G4: TRUE | H4: TRUE | I4: TRUE | J4: TRUE | K4: TRUE
A5: Taux de réponse brute par filière | B5: 1 | C5: Réactivité de réponse par filière. | D5: Réponses envoyées / besoins exprimés (filière). | E5: Atteindre un taux de réponse brute ≥ 90% par filière chaque mois d’ici le 31/12/2026. | F5: TRUE | G5: TRUE | H5: TRUE | I5: TRUE | J5: TRUE | K5: TRUE
A6: Taux de réponse net par filière | B6: 1 | C6: Pertinence perçue par filière. | D6: Réponses avec retour / besoins exprimés (filière). | E6: Atteindre un taux de réponse net ≥ 70% par filière chaque mois d’ici le 31/12/2026. | F6: TRUE | G6: TRUE | H6: TRUE | I6: TRUE | J6: TRUE | K6: TRUE
A7: Taux de soutenance par besoin par filière | B7: 1 | C7: Mobilisation soutenances par filière. | D7: Soutenances / besoins (filière). | E7: Atteindre un taux de soutenance ≥ 60% par besoin et par filière chaque trimestre jusqu’au 31/12/2026. | F7: TRUE | G7: TRUE | H7: TRUE | I7: TRUE | J7: TRUE | K7: TRUE
A8: Taux de transformation par filière | B8: 1 | C8: Conversion par filière. | D8: Missions gagnées / propositions (filière). | E8: Atteindre un taux de transformation ≥ 25% par filière d’ici le 31/12/2026. | F8: TRUE | G8: TRUE | H8: TRUE | I8: TRUE | J8: TRUE | K8: TRUE
A9: Taux de conversion après soutenance par filière | B9: 1 | C9: Efficacité soutenance par filière. | D9: Missions gagnées / soutenances (filière). | E9: ≥ 30 % | F9: TRUE | G9: TRUE | H9: TRUE | I9: TRUE | J9: TRUE | K9: TRUE
A10: Taux de rebond consultant par filière | B10: 1 | C10: Fidélisation par filière. | D10: Consultants en rebond / fins de mission (filière). | E10: ≥ 50 % | F10: TRUE | G10: TRUE | H10: TRUE | I10: TRUE | J10: TRUE | K10: TRUE
A11: Taux de churn consultant par filière | C11: Attrition par filière. | D11: Consultants sortis / actifs (filière). | E11: < 10 % | F11: TRUE | G11: TRUE | H11: TRUE | I11: TRUE | J11: TRUE | K11: TRUE
A12: Nb d’offres packagées par filière | C12: Industrialisation de l’offre par filière. | D12: Comptage offres packagées actives. | E12: Disposer d’au moins 2 offres packagées actives par filière au 31/12/2026. | F12: TRUE | G12: TRUE | H12: TRUE | I12: TRUE | J12: TRUE | K12: TRUE
A13: Taux de succès offres packagées par filière | C13: Performance des offres packagées. | D13: Gagnées / présentées (filière). | E13: Atteindre un taux de succès des offres packagées ≥ 35% par filière d’ici le 31/12/2026. | F13: TRUE | G13: TRUE | H13: TRUE | I13: TRUE | J13: TRUE | K13: TRUE
A14: Nb de référencements par filière | C14: Ancrage client par filière. | D14: Comptage référencements par filière. | E14: Obtenir ≥ 2 nouveaux référencements par filière en 2026 (échéance 31/12/2026). | F14: TRUE | G14: TRUE | H14: TRUE | I14: TRUE | J14: TRUE | K14: TRUE
A15: Taux de succès AO complexes par filière | C15: Performance sur AO complexes par filière. | D15: AO gagnés / répondus (filière). | E15: Atteindre un taux de succès ≥ 30% sur AO complexes par filière d’ici le 31/12/2026. | F15: TRUE | G15: TRUE | H15: TRUE | I15: TRUE | J15: TRUE | K15: TRUE
A16: Nb de régies éligibles à une bascule CDS par filière | C16: Opportunités CDS détectées (filière). | D16: Comptage régies “éligibles CDS” (filière). | E16: Augmenter de +50% vs N-1 le nombre de régies éligibles CDS par filière d’ici le 31/12/2026. | F16: TRUE | G16: TRUE | H16: TRUE | I16: TRUE | J16: TRUE | K16: TRUE
A17: Nb de tentatives de bascule CDS par filière | C17: Effort de transformation par filière. | D17: Comptage tentatives (filière). | E17: Réaliser au moins 1 tentative de bascule CDS par filière et par trimestre jusqu’au 31/12/2026. | F17: TRUE | G17: TRUE | H17: TRUE | I17: TRUE | J17: TRUE | K17: TRUE
A18: Nb de bascules CDS réussies par filière | C18: Succès de transformation (filière). | D18: Comptage bascules réussies (filière). | E18: Obtenir au moins 1 bascule CDS réussie par filière et par trimestre jusqu’au 31/12/2026. | F18: TRUE | G18: TRUE | H18: TRUE | I18: TRUE | J18: TRUE | K18: TRUE
A19: Taux de bascule régie → CDS par filière | C19: Efficacité de transformation (filière). | D19: Bascules réussies / régies éligibles (filière). | E19: 10–20 % | F19: TRUE | G19: TRUE | H19: TRUE | I19: TRUE | J19: TRUE | K19: TRUE
A20: CA gagné via bascule CDS par filière | C20: Impact financier des bascules par filière. | D20: Σ (CA CDS – CA régie) (filière). | E20: Accroître le CA net généré par les bascules CDS d’au moins +20% vs N-1 d’ici le 31/12/2026. | F20: TRUE | G20: TRUE | H20: TRUE | I20: TRUE | J20: TRUE | K20: TRUE
A21: Répartition motifs d’échec bascule par filière | C21: Analyse des causes d’échec par filière. | D21: % par motif. | E21: Ramener chacun des 2 motifs dominants d’échec < 25% d’ici le 31/12/2026. | F21: TRUE | G21: TRUE | H21: TRUE | I21: TRUE | J21: TRUE | K21: TRUE
A22: Délai moyen de réponse à AO par filière | C22: Réactivité AO par filière. | D22: Date réponse – date réception (moyenne) (filière). | E22: DT <24h ; AT <48h ; LF <24h | F22: TRUE | G22: TRUE | H22: TRUE | I22: TRUE | J22: TRUE | K22: TRUE
... A45: Taux de croissance des missions packagées (par filière) | C45: Évolution du volume ou du CA des missions packagées dans la filière. | D45: (Nb missions packagées N – N-1) / N-1 (filière) ou (CA N – N-1) / N-1 (filière). | E45: Assurer une croissance des missions packagées ≥ 10% par trimestre en 2026. | F45: TRUE | G45: TRUE | H45: TRUE | I45: TRUE | J45: TRUE | K45: TRUE

Sheet Mapping Boond
A1: KPI | B1: Nomencalture Wekey | C1: Priorité | D1: Mesure | E1: Indication | F1: Champs BoondManager | G1: Mode de calcul
A2: Taux de rebond consultant par filière | B2: Ressources | D2: =VLOOKUP(A2,Audit_SMART!$A$1:$D$45,3,FALSE) -> Fidélisation par filière. | E2: =VLOOKUP(A2,Audit_SMART!$A$1:$D$45,4,FALSE) -> Consultants en rebond / fins de mission (filière). | F2: Consultants, Historique missions, Statut actif | G2: Consultants en rebond / fins de mission (filière).
A3: Taux de churn consultant par filière | B3: Ressources | D3: =VLOOKUP(A3,Audit_SMART!$A$1:$D$45,3,FALSE) -> Attrition par filière. | E3: =VLOOKUP(A3,Audit_SMART!$A$1:$D$45,4,FALSE) -> Consultants sortis / actifs (filière). | F3: Consultants, Historique missions, Statut actif | G3: Consultants sortis / actifs (filière).
A4: Taux de succès AO complexes par filière | B4: Positionnements | D4: =VLOOKUP(A4,Audit_SMART!$A$1:$D$45,3,FALSE) -> Performance sur AO complexes par filière. | E4: =VLOOKUP(A4,Audit_SMART!$A$1:$D$45,4,FALSE) -> AO gagnés / répondus (filière). | F4: Tags filière, Opportunités, Candidats, Missions | G4: AO gagnés / répondus (filière).
A5: % dossiers validés par un LF (par filière) | B5: Positionnements | D5: =VLOOKUP(A5,Audit_SMART!$A$1:$D$45,3,FALSE) -> Qualité technique garantie par filière. | E5: =VLOOKUP(A5,Audit_SMART!$A$1:$D$45,4,FALSE) -> Nb dossiers validés / nb créés (filière). | F5: Tags filière, Opportunités, Candidats, Missions | G5: Nb dossiers validés / nb créés (filière).
A6: % consultants préparés avant entretien (par filière) | B6: Positionnements | D6: =VLOOKUP(A6,Audit_SMART!$A$1:$D$45,3,FALSE) -> Qualité de préparation par filière. | E6: =VLOOKUP(A6,Audit_SMART!$A$1:$D$45,4,FALSE) -> Nb consultants préparés / nb envoyés en entretien (filière). | F6: Tags filière, Opportunités, Candidats, Missions | G6: Nb consultants préparés / nb envoyés en entretien (filière).
A7: Taux de couverture site-client (≥3 profils par site majeur) | B7: Positionnements | D7: =VLOOKUP(A7,Audit_SMART!$A$1:$D$45,3,FALSE) -> Capacité à livrer par site-clé. | E7: =VLOOKUP(A7,Audit_SMART!$A$1:$D$45,4,FALSE) -> % typologies avec ≥3 profils par site. | F7: Tags filière, Opportunités, Candidats, Missions | G7: % typologies avec ≥3 profils par site.
A8: Taux de présentation express (<1h, 3 profils présentés) | B8: Positionnements | D8: =VLOOKUP(A8,Audit_SMART!$A$1:$D$45,3,FALSE) -> Réactivité “time-to-present”. | E8: =VLOOKUP(A8,Audit_SMART!$A$1:$D$45,4,FALSE) -> Nb cas avec 3 profils <1h / nb besoins récurrents. | F8: Tags filière, Opportunités, Candidats, Missions | G8: Nb cas avec 3 profils <1h / nb besoins récurrents.
A9: % de prestations en régie (par filière) | B9: Positionnements | D9: =VLOOKUP(A9,Audit_SMART!$A$1:$D$45,3,FALSE) -> Part des missions en régie dans la filière considérée. | E9: =VLOOKUP(A9,Audit_SMART!$A$1:$D$45,4,FALSE) -> Nb missions régie (filière) / Nb missions totales (filière). | F9: Tags filière, Opportunités, Candidats, Missions | G9: Nb missions régie (filière) / Nb missions totales (filière).
A10: Nb candidats en vivier par filière | B10: Candidats | D10: =VLOOKUP(A10,Audit_SMART!$A$1:$D$45,3,FALSE) -> Taille du vivier par filière. | E10: =VLOOKUP(A10,Audit_SMART!$A$1:$D$45,4,FALSE) -> Comptage profils actifs dans le vivier. | F10: Candidats (tag filière), Statut actif, Date mise à jour | G10: Comptage profils actifs dans le vivier.
A11: Croissance vivier par filière | B11: Candidats | D11: =VLOOKUP(A11,Audit_SMART!$A$1:$D$45,3,FALSE) -> Évolution du vivier par filière. | E11: =VLOOKUP(A11,Audit_SMART!$A$1:$D$45,4,FALSE) -> Δ vivier filière / période. | F11: Candidats (tag filière), Statut actif, Date mise à jour | G11: Δ vivier filière / période.
A12: % candidats pertinents avec dossier prêt à l’emploi (par filière) | B12: Candidats | D12: =VLOOKUP(A12,Audit_SMART!$A$1:$D$45,3,FALSE) -> Disponibilité des dossiers par filière. | E12: =VLOOKUP(A12,Audit_SMART!$A$1:$D$45,4,FALSE) -> Nb candidats pertinents avec dossier / nb pertinents (filière). | F12: Candidats (tag filière), Statut actif, Date mise à jour | G12: Nb candidats pertinents avec dossier / nb pertinents (filière).
A13: % candidats avec références collectées (par filière) | B13: Candidats | D13: =VLOOKUP(A13,Audit_SMART!$A$1:$D$45,3,FALSE) -> Réflexe de collecte par filière. | E13: =VLOOKUP(A13,Audit_SMART!$A$1:$D$45,4,FALSE) -> Nb candidats avec refs / nb entretiens (filière). | F13: Candidats (tag filière), Statut actif, Date mise à jour | G13: Nb candidats avec refs / nb entretiens (filière).
... A45: Nb de typologies de missions récurrentes identifiées par filière | B45: Besoins | D45: =VLOOKUP(A45,Audit_SMART!$A$1:$D$45,3,FALSE) -> Cartographie des postes récurrents par filière. | E45: =VLOOKUP(A45,Audit_SMART!$A$1:$D$45,4,FALSE) -> Comptage typologies récurrentes actives. | F45: Tags ou Custom Fields (Typologie), Viviers | G45: Comptage typologies récurrentes actives.

Sheet Saisie_Donnees
A1: Date | B1: Périmètre (Filière) | C1: KPI | D1: Valeur | E1: Commentaire
A2: 46002 | B2: FEA | C2: Nb candidats en vivier par filière | D2: 26 | E2: FEA&KONA Napé&Dispo<3mois
A3: 46002 | B3: FEA | C3: Croissance vivier par filière
A4: 46002 | B4: FEA | C4: % candidats pertinents avec dossier prêt à l’emploi (par filière)
A5: 46002 | B5: FEA | C5: % candidats avec références collectées (par filière)
A6: 46002 | B6: FEA | C6: % candidats avec ≥1 référence vérifiée (par filière)
A7: 46002 | B7: FEA | C7: Nb de viviers actifs par typologie récurrente
A8: 46002 | B8: FEA | C8: Nb moyen de profils disponibles par vivier
A9: 46002 | B9: FEA | C9: Taux de complétude des viviers (≥3 profils par typologie)
A10: 46002 | B10: FEA | C10: Délai de mise à disposition d’un vivier
A11: 46002 | B11: FEA | C11: % de viviers construits avec apport DT vs LF direct
A12: 46002 | B12: FEA | C12: Taux de renouvellement des viviers (profils mis à jour / 6 mois)
A13: 46002 | B13: FEA | C13: Taux de rebond consultant par filière
A14: 46002 | B14: FEA | C14: Taux de churn consultant par filière
... A45: 46002 | B45: FEA | C45: Nb de typologies de missions récurrentes identifiées par filière

Sheet Taxomonie
A3: Étiquettes de lignes | B3: Nombre de KPI
A4: Besoins | B4: 25 | C4: Opportunités ou demandes exprimées par un client (ex. mission à staffer, AO).
A5: Candidats | B5: 11 | C5: Profils identifiés pour répondre aux besoins (internes ou externes).
A6: Positionnements | B6: 6 | C6: Action de proposer un candidat sur un besoin (avec dossier complet).
A7: Ressources | B7: 2 | C7: Consultants en mission (interne ou externe) ou disponibles pour positionnement.
A8: Total général | B8: 44
C13: Vivier passif | E13: Vivier actif
C15: Définition : Ensemble de candidats non activement suivis, profils anciens ou indisponibles. | E15: Définition : Ensemble de candidats disponibles et à jour, prêts à être positionnés rapidement.
C16: Critères typiques : | E16: Critères typiques :
C18: Profil incomplet ou obsolète. | E18: Profil complet (CV, dossier validé, références vérifiées).
C19: Disponibilité inconnue ou lointaine. | E19: Disponibilité confirmée (immédiate ou à court terme).
C20: Dernière mise à jour > 6 mois. | E20: Dernière mise à jour récente (ex. < 3 mois).
C21: Statut : Inactif ou À recontacter. | E21: Statut : Actif dans BoondManager.
C24: Indicateur business : Potentiel à réactiver → KPI comme Taux de renouvellement des viviers. | E24: Indicateur business : Capacité immédiate à répondre à un besoin → KPI comme Nb moyen de profils disponibles par vivier, Taux de complétude des viviers.
E29: Créer des tags ou champs personnalisés
E30: Allez dans Administration → Paramètres → Champs personnalisés.
E31: Créez un champ Type : Liste déroulante nommé :
E32: Statut vivier
E33: avec valeurs :
E34: Actif
E35: Passif
E36: Associez ce champ à l’entité Candidat.
E39: Automatiser la classification
E40: Dans Administration → Automatisations :
E41: Créez une règle :
E42: Condition : Dernière mise à jour < 90 jours ET Statut = Actif.
... E46: Action : Tag = Passif.

Sheet Dashboard
A1: Instructions Dashboard
A2: Créez un TCD depuis 'Saisie_Donnees' (Valeur par KPI et Filière, filtré par Date).
A3: Ajoutez des segments (Date, Filière, KPI) et des cartes d'indicateurs (Objectif, Réalisé, Écart, % Atteint).
A8: ?Indication de filiere
A9: ?Forfait, regie, packagées (boond) = Packagée et forfait, est ce la meme chose?
A10: ? Process bascule CDS vers Filiere
